Workbook

Sheet CBIC_Late_Fee_Relief_Windows_1
A1: Relief Window ID | B1: Notification No | C1: Relief Type | D1: Tax Period From | E1: Tax Period To | F1: Filing Date From | G1: Filing Date To | H1: Return Type | I1: Max Late Fee Allowed | J1: Window Priority | K1: Legal Notes
A2: AMN18_JUL17_SEP18 | B2: 76/2018-CT | C2: Amnesty | D2: Jul-2017 | E2: Sep-2018 | F2: 22-12-2018 | G2: 31-03-2019 | H2: ALL | I2: 0 | J2: 1 | K2: Full waiver only if filed in window
A3: C19_Mar-2020_NIL | B3: 41/2020-CT | C3: COVID-19 | D3: Mar-2020 | E3: Mar-2020 | F3: 01-03-2020 | G3: 30-09-2020 | H3: NIL | I3: 0 | J3: 2 | K3: COVID NIL waiver
A4: C19_Mar-2020_NONNIL | B4: 41/2020-CT | C4: COVID-19 | D4: Mar-2020 | E4: Mar-2020 | F4: 01-03-2020 | G4: 30-09-2020 | H4: NON-NIL | I4: 1000 | J4: 2 | K4: COVID NON-NIL cap
A5: C19_Apr-2020_NIL | B5: 41/2020-CT | C5: COVID-19 | D5: Apr-2020 | E5: Apr-2020 | F5: 01-03-2020 | G5: 30-09-2020 | H5: NIL | I5: 0 | J5: 2 | K5: COVID NIL waiver
A6: C19_Apr-2020_NONNIL | B6: 41/2020-CT | C6: COVID-19 | D6: Apr-2020 | E6: Apr-2020 | F6: 01-03-2020 | G6: 30-09-2020 | H6: NON-NIL | I6: 1000 | J6: 2 | K6: COVID NON-NIL cap
A7: C19_May-2020_NIL | B7: 41/2020-CT | C7: COVID-19 | D7: May-2020 | E7: May-2020 | F7: 01-03-2020 | G7: 30-09-2020 | H7: NIL | I7: 0 | J7: 2 | K7: COVID NIL waiver
A8: C19_May-2020_NONNIL | B8: 41/2020-CT | C8: COVID-19 | D8: May-2020 | E8: May-2020 | F8: 01-03-2020 | G8: 30-09-2020 | H8: NON-NIL | I8: 1000 | J8: 2 | K8: COVID NON-NIL cap
A9: C19_Jun-2020_NIL | B9: 41/2020-CT | C9: COVID-19 | D9: Jun-2020 | E9: Jun-2020 | F9: 01-03-2020 | G9: 30-09-2020 | H9: NIL | I9: 0 | J9: 2 | K9: COVID NIL waiver
A10: C19_Jun-2020_NONNIL | B10: 41/2020-CT | C10: COVID-19 | D10: Jun-2020 | E10: Jun-2020 | F10: 01-03-2020 | G10: 30-09-2020 | H10: NON-NIL | I10: 1000 | J10: 2 | K10: COVID NON-NIL cap
A11: C19_Jul-2020_NIL | B11: 41/2020-CT | C11: COVID-19 | D11: Jul-2020 | E11: Jul-2020 | F11: 01-03-2020 | G11: 30-09-2020 | H11: NIL | I11: 0 | J11: 2 | K11: COVID NIL waiver
A12: C19_Jul-2020_NONNIL | B12: 41/2020-CT | C12: COVID-19 | D12: Jul-2020 | E12: Jul-2020 | F12: 01-03-2020 | G12: 30-09-2020 | H12: NON-NIL | I12: 1000 | J12: 2 | K12: COVID NON-NIL cap
A13: NIL_STRUCT | B13: Section 47 | C13: Structural | D13: Jul-2017 | E13: Dec-2099 | F13: 01-07-2017 | G13: 31-12-2099 | H13: NIL | I13: 500 | J13: 5 | K13: Structural NIL cap
A14: STAT_FALLBACK | B14: Section 47 | C14: Statutory | D14: Jul-2017 | E14: Dec-2099 | F14: 01-07-2017 | G14: 31-12-2099 | H14: ALL | I14: 10000 | J14: 6 | K14: Statutory fallback

Sheet CALCULATOR
A1: GSTIN | B1: Tax Period | C1: Filing Date | D1: Return Type | E1: Delay Days | F1: Normal Late Fee | G1: Allowed Max Late Fee | H1: Final Late Fee | I1: Relief Applied (Notification)
A2: =TEST_DATA!A2 -> 27AAAAA0002Z5 | B2: =TEST_DATA!B2 -> May-2020 | C2: =TEST_DATA!C2 -> 44059 | D2: =TEST_DATA!D2 -> NIL | E2: =TEST_DATA!E2 -> 1126 | F2: =MIN(E2*200,10000) -> 10000 | G2: =_xludf.MINIFS(CBIC_Late_Fee_Relief_Windows_1!$I$2:$I$100,CBIC_Late_Fee_Relief_Windows_1!$D$2:$D$100,"<="&B2,CBIC_Late_Fee_Relief_Windows_1!$E$2:$E$100,">="&B2,CBIC_Late_Fee_Relief_Windows_1!$F$2:$F$100,"<="&C2,CBIC_Late_Fee_Relief_Windows_1!$G$2:$G$100,">="&C2,CBIC_Late_Fee_Relief_Windows_1!$H$2:$H$100,D2) -> #NAME? | H2: =MIN(F2,G2) -> #NAME? | I2: =INDEX(CBIC_Late_Fee_Relief_Windows_1!$B$2:$B$100,MATCH(G2,CBIC_Late_Fee_Relief_Windows_1!$I$2:$I$100,0)) -> #NAME?
A3: =TEST_DATA!A3 -> 27AAAAA0003Z5 | B3: =TEST_DATA!B3 -> Feb-2018 | C3: =TEST_DATA!C3 -> 43374 | D3: =TEST_DATA!D3 -> NIL | E3: =TEST_DATA!E3 -> 419 | F3: =MIN(E3*300,10000) -> 10000 | G3: =_xludf.MINIFS(CBIC_Late_Fee_Relief_Windows_1!$I$3:$I$100,CBIC_Late_Fee_Relief_Windows_1!$D$3:$D$100,"<="&B3,CBIC_Late_Fee_Relief_Windows_1!$E$3:$E$100,">="&B3,CBIC_Late_Fee_Relief_Windows_1!$F$3:$F$100,"<="&C3,CBIC_Late_Fee_Relief_Windows_1!$G$3:$G$100,">="&C3,CBIC_Late_Fee_Relief_Windows_1!$H$3:$H$100,D3) -> #NAME? | H3: =MIN(F3,G3) -> #NAME? | I3: =INDEX(CBIC_Late_Fee_Relief_Windows_1!$B$3:$B$100,MATCH(G3,CBIC_Late_Fee_Relief_Windows_1!$I$3:$I$100,0)) -> #NAME?
A4: =TEST_DATA!A4 -> 27AAAAA0004Z5 | B4: =TEST_DATA!B4 -> Jun-2020 | C4: =TEST_DATA!C4 -> 44009 | D4: =TEST_DATA!D4 -> NON-NIL | E4: =TEST_DATA!E4 -> 130 | F4: =MIN(E4*400,10000) -> 10000 | G4: =_xludf.MINIFS(CBIC_Late_Fee_Relief_Windows_1!$I$4:$I$100,CBIC_Late_Fee_Relief_Windows_1!$D$4:$D$100,"<="&B4,CBIC_Late_Fee_Relief_Windows_1!$E$4:$E$100,">="&B4,CBIC_Late_Fee_Relief_Windows_1!$F$4:$F$100,"<="&C4,CBIC_Late_Fee_Relief_Windows_1!$G$4:$G$100,">="&C4,CBIC_Late_Fee_Relief_Windows_1!$H$4:$H$100,D4) -> #NAME? | H4: =MIN(F4,G4) -> #NAME? | I4: =INDEX(CBIC_Late_Fee_Relief_Windows_1!$B$4:$B$100,MATCH(G4,CBIC_Late_Fee_Relief_Windows_1!$I$4:$I$100,0)) -> #NAME?
A5: =TEST_DATA!A5 -> 27AAAAA0005Z5 | B5: =TEST_DATA!B5 -> Jul-2017 | C5: =TEST_DATA!C5 -> 43108 | D5: =TEST_DATA!D5 -> NIL | E5: =TEST_DATA!E5 -> 952 | F5: =MIN(E5*500,10000) -> 10000 | G5: =_xludf.MINIFS(CBIC_Late_Fee_Relief_Windows_1!$I$5:$I$100,CBIC_Late_Fee_Relief_Windows_1!$D$5:$D$100,"<="&B5,CBIC_Late_Fee_Relief_Windows_1!$E$5:$E$100,">="&B5,CBIC_Late_Fee_Relief_Windows_1!$F$5:$F$100,"<="&C5,CBIC_Late_Fee_Relief_Windows_1!$G$5:$G$100,">="&C5,CBIC_Late_Fee_Relief_Windows_1!$H$5:$H$100,D5) -> #NAME? | H5: =MIN(F5,G5) -> #NAME? | I5: =INDEX(CBIC_Late_Fee_Relief_Windows_1!$B$5:$B$100,MATCH(G5,CBIC_Late_Fee_Relief_Windows_1!$I$5:$I$100,0)) -> #NAME?
A6: =TEST_DATA!A6 -> 27AAAAA0006Z5 | B6: =TEST_DATA!B6 -> Jun-2019 | C6: =TEST_DATA!C6 -> 43574 | D6: =TEST_DATA!D6 -> NIL | E6: =TEST_DATA!E6 -> 2932 | F6: =MIN(E6*600,10000) -> 10000 | G6: =_xludf.MINIFS(CBIC_Late_Fee_Relief_Windows_1!$I$6:$I$100,CBIC_Late_Fee_Relief_Windows_1!$D$6:$D$100,"<="&B6,CBIC_Late_Fee_Relief_Windows_1!$E$6:$E$100,">="&B6,CBIC_Late_Fee_Relief_Windows_1!$F$6:$F$100,"<="&C6,CBIC_Late_Fee_Relief_Windows_1!$G$6:$G$100,">="&C6,CBIC_Late_Fee_Relief_Windows_1!$H$6:$H$100,D6) -> #NAME? | H6: =MIN(F6,G6) -> #NAME? | I6: =INDEX(CBIC_Late_Fee_Relief_Windows_1!$B$6:$B$100,MATCH(G6,CBIC_Late_Fee_Relief_Windows_1!$I$6:$I$100,0)) -> #NAME?
A7: =TEST_DATA!A7 -> 27AAAAA0007Z5 | B7: =TEST_DATA!B7 -> May-2020 | C7: =TEST_DATA!C7 -> 44690 | D7: =TEST_DATA!D7 -> NIL | E7: =TEST_DATA!E7 -> 1839 | F7: =MIN(E7*700,10000) -> 10000 | G7: =_xludf.MINIFS(CBIC_Late_Fee_Relief_Windows_1!$I$7:$I$100,CBIC_Late_Fee_Relief_Windows_1!$D$7:$D$100,"<="&B7,CBIC_Late_Fee_Relief_Windows_1!$E$7:$E$100,">="&B7,CBIC_Late_Fee_Relief_Windows_1!$F$7:$F$100,"<="&C7,CBIC_Late_Fee_Relief_Windows_1!$G$7:$G$100,">="&C7,CBIC_Late_Fee_Relief_Windows_1!$H$7:$H$100,D7) -> #NAME? | H7: =MIN(F7,G7) -> #NAME? | I7: =INDEX(CBIC_Late_Fee_Relief_Windows_1!$B$7:$B$100,MATCH(G7,CBIC_Late_Fee_Relief_Windows_1!$I$7:$I$100,0)) -> #NAME?
A8: =TEST_DATA!A8 -> 27AAAAA0008Z5 | B8: =TEST_DATA!B8 -> Mar-2020 | C8: =TEST_DATA!C8 -> 44400 | D8: =TEST_DATA!D8 -> NIL | E8: =TEST_DATA!E8 -> 653 | F8: =MIN(E8*800,10000) -> 10000 | G8: =_xludf.MINIFS(CBIC_Late_Fee_Relief_Windows_1!$I$8:$I$100,CBIC_Late_Fee_Relief_Windows_1!$D$8:$D$100,"<="&B8,CBIC_Late_Fee_Relief_Windows_1!$E$8:$E$100,">="&B8,CBIC_Late_Fee_Relief_Windows_1!$F$8:$F$100,"<="&C8,CBIC_Late_Fee_Relief_Windows_1!$G$8:$G$100,">="&C8,CBIC_Late_Fee_Relief_Windows_1!$H$8:$H$100,D8) -> #NAME? | H8: =MIN(F8,G8) -> #NAME? | I8: =INDEX(CBIC_Late_Fee_Relief_Windows_1!$B$8:$B$100,MATCH(G8,CBIC_Late_Fee_Relief_Windows_1!$I$8:$I$100,0)) -> #NAME?
A9: =TEST_DATA!A9 -> 27AAAAA0009Z5 | B9: =TEST_DATA!B9 -> Jul-2020 | C9: =TEST_DATA!C9 -> 44696 | D9: =TEST_DATA!D9 -> NON-NIL | E9: =TEST_DATA!E9 -> 1138 | F9: =MIN(E9*900,10000) -> 10000 | G9: =_xludf.MINIFS(CBIC_Late_Fee_Relief_Windows_1!$I$9:$I$100,CBIC_Late_Fee_Relief_Windows_1!$D$9:$D$100,"<="&B9,CBIC_Late_Fee_Relief_Windows_1!$E$9:$E$100,">="&B9,CBIC_Late_Fee_Relief_Windows_1!$F$9:$F$100,"<="&C9,CBIC_Late_Fee_Relief_Windows_1!$G$9:$G$100,">="&C9,CBIC_Late_Fee_Relief_Windows_1!$H$9:$H$100,D9) -> #NAME? | H9: =MIN(F9,G9) -> #NAME? | I9: =INDEX(CBIC_Late_Fee_Relief_Windows_1!$B$9:$B$100,MATCH(G9,CBIC_Late_Fee_Relief_Windows_1!$I$9:$I$100,0)) -> #NAME?
A10: =TEST_DATA!A10 -> 27AAAAA0010Z5 | B10: =TEST_DATA!B10 -> Nov-2017 | C10: =TEST_DATA!C10 -> 43357 | D10: =TEST_DATA!D10 -> NON-NIL | E10: =TEST_DATA!E10 -> 418 | F10: =MIN(E10*1000,10000) -> 10000 | G10: =_xludf.MINIFS(CBIC_Late_Fee_Relief_Windows_1!$I$10:$I$100,CBIC_Late_Fee_Relief_Windows_1!$D$10:$D$100,"<="&B10,CBIC_Late_Fee_Relief_Windows_1!$E$10:$E$100,">="&B10,CBIC_Late_Fee_Relief_Windows_1!$F$10:$F$100,"<="&C10,CBIC_Late_Fee_Relief_Windows_1!$G$10:$G$100,">="&C10,CBIC_Late_Fee_Relief_Windows_1!$H$10:$H$100,D10) -> #NAME? | H10: =MIN(F10,G10) -> #NAME? | I10: =INDEX(CBIC_Late_Fee_Relief_Windows_1!$B$10:$B$100,MATCH(G10,CBIC_Late_Fee_Relief_Windows_1!$I$10:$I$100,0)) -> #NAME?
A11: =TEST_DATA!A11 -> 27AAAAA0011Z5 | B11: =TEST_DATA!B11 -> Sep-2017 | C11: =TEST_DATA!C11 -> 43695 | D11: =TEST_DATA!D11 -> NIL | E11: =TEST_DATA!E11 -> 1470 | F11: =MIN(E11*1100,10000) -> 10000 | G11: =_xludf.MINIFS(CBIC_Late_Fee_Relief_Windows_1!$I$11:$I$100,CBIC_Late_Fee_Relief_Windows_1!$D$11:$D$100,"<="&B11,CBIC_Late_Fee_Relief_Windows_1!$E$11:$E$100,">="&B11,CBIC_Late_Fee_Relief_Windows_1!$F$11:$F$100,"<="&C11,CBIC_Late_Fee_Relief_Windows_1!$G$11:$G$100,">="&C11,CBIC_Late_Fee_Relief_Windows_1!$H$11:$H$100,D11) -> #NAME? | H11: =MIN(F11,G11) -> #NAME? | I11: =INDEX(CBIC_Late_Fee_Relief_Windows_1!$B$11:$B$100,MATCH(G11,CBIC_Late_Fee_Relief_Windows_1!$I$11:$I$100,0)) -> #NAME?
A12: =TEST_DATA!A12 -> 27AAAAA0012Z5 | B12: =TEST_DATA!B12 -> Mar-2023 | C12: =TEST_DATA!C12 -> 44874 | D12: =TEST_DATA!D12 -> NON-NIL | E12: =TEST_DATA!E12 -> 177 | F12: =MIN(E12*1200,10000) -> 10000 | G12: =_xludf.MINIFS(CBIC_Late_Fee_Relief_Windows_1!$I$12:$I$100,CBIC_Late_Fee_Relief_Windows_1!$D$12:$D$100,"<="&B12,CBIC_Late_Fee_Relief_Windows_1!$E$12:$E$100,">="&B12,CBIC_Late_Fee_Relief_Windows_1!$F$12:$F$100,"<="&C12,CBIC_Late_Fee_Relief_Windows_1!$G$12:$G$100,">="&C12,CBIC_Late_Fee_Relief_Windows_1!$H$12:$H$100,D12) -> #NAME? | H12: =MIN(F12,G12) -> #NAME? | I12: =INDEX(CBIC_Late_Fee_Relief_Windows_1!$B$12:$B$100,MATCH(G12,CBIC_Late_Fee_Relief_Windows_1!$I$12:$I$100,0)) -> #NAME?
A13: =TEST_DATA!A13 -> 27AAAAA0013Z5 | B13: =TEST_DATA!B13 -> Jan-2021 | C13: =TEST_DATA!C13 -> 45347 | D13: =TEST_DATA!D13 -> NIL | E13: =TEST_DATA!E13 -> 1550 | F13: =MIN(E13*1300,10000) -> 10000 | G13: =_xludf.MINIFS(CBIC_Late_Fee_Relief_Windows_1!$I$13:$I$100,CBIC_Late_Fee_Relief_Windows_1!$D$13:$D$100,"<="&B13,CBIC_Late_Fee_Relief_Windows_1!$E$13:$E$100,">="&B13,CBIC_Late_Fee_Relief_Windows_1!$F$13:$F$100,"<="&C13,CBIC_Late_Fee_Relief_Windows_1!$G$13:$G$100,">="&C13,CBIC_Late_Fee_Relief_Windows_1!$H$13:$H$100,D13) -> #NAME? | H13: =MIN(F13,G13) -> #NAME? | I13: =INDEX(CBIC_Late_Fee_Relief_Windows_1!$B$13:$B$100,MATCH(G13,CBIC_Late_Fee_Relief_Windows_1!$I$13:$I$100,0)) -> #NAME?
A14: =TEST_DATA!A14 -> 27AAAAA0014Z5 | B14: =TEST_DATA!B14 -> Sep-2017 | C14: =TEST_DATA!C14 -> 44047 | D14: =TEST_DATA!D14 -> NON-NIL | E14: =TEST_DATA!E14 -> 2574 | F14: =MIN(E14*1400,10000) -> 10000 | G14: =_xludf.MINIFS(CBIC_Late_Fee_Relief_Windows_1!$I$14:$I$100,CBIC_Late_Fee_Relief_Windows_1!$D$14:$D$100,"<="&B14,CBIC_Late_Fee_Relief_Windows_1!$E$14:$E$100,">="&B14,CBIC_Late_Fee_Relief_Windows_1!$F$14:$F$100,"<="&C14,CBIC_Late_Fee_Relief_Windows_1!$G$14:$G$100,">="&C14,CBIC_Late_Fee_Relief_Windows_1!$H$14:$H$100,D14) -> #NAME? | H14: =MIN(F14,G14) -> #NAME? | I14: =INDEX(CBIC_Late_Fee_Relief_Windows_1!$B$14:$B$100,MATCH(G14,CBIC_Late_Fee_Relief_Windows_1!$I$14:$I$100,0)) -> #NAME?
A15: =TEST_DATA!A15 -> 27AAAAA0015Z5 | B15: =TEST_DATA!B15 -> Apr-2020 | C15: =TEST_DATA!C15 -> 44571 | D15: =TEST_DATA!D15 -> NIL | E15: =TEST_DATA!E15 -> 2885 | F15: =MIN(E15*1500,10000) -> 10000 | G15: =_xludf.MINIFS(CBIC_Late_Fee_Relief_Windows_1!$I$15:$I$100,CBIC_Late_Fee_Relief_Windows_1!$D$15:$D$100,"<="&B15,CBIC_Late_Fee_Relief_Windows_1!$E$15:$E$100,">="&B15,CBIC_Late_Fee_Relief_Windows_1!$F$15:$F$100,"<="&C15,CBIC_Late_Fee_Relief_Windows_1!$G$15:$G$100,">="&C15,CBIC_Late_Fee_Relief_Windows_1!$H$15:$H$100,D15) -> #NAME? | H15: =MIN(F15,G15) -> #NAME? | I15: =INDEX(CBIC_Late_Fee_Relief_Windows_1!$B$15:$B$100,MATCH(G15,CBIC_Late_Fee_Relief_Windows_1!$I$15:$I$100,0)) -> #NAME?
A16: =TEST_DATA!A16 -> 27AAAAA0016Z5 | B16: =TEST_DATA!B16 -> Sep-2017 | C16: =TEST_DATA!C16 -> 43010 | D16: =TEST_DATA!D16 -> NIL | E16: =TEST_DATA!E16 -> 1185 | F16: =MIN(E16*1600,10000) -> 10000 | G16: =_xludf.MINIFS(CBIC_Late_Fee_Relief_Windows_1!$I$16:$I$100,CBIC_Late_Fee_Relief_Windows_1!$D$16:$D$100,"<="&B16,CBIC_Late_Fee_Relief_Windows_1!$E$16:$E$100,">="&B16,CBIC_Late_Fee_Relief_Windows_1!$F$16:$F$100,"<="&C16,CBIC_Late_Fee_Relief_Windows_1!$G$16:$G$100,">="&C16,CBIC_Late_Fee_Relief_Windows_1!$H$16:$H$100,D16) -> #NAME? | H16: =MIN(F16,G16) -> #NAME? | I16: =INDEX(CBIC_Late_Fee_Relief_Windows_1!$B$16:$B$100,MATCH(G16,CBIC_Late_Fee_Relief_Windows_1!$I$16:$I$100,0)) -> #NAME?
A17: =TEST_DATA!A17 -> 27AAAAA0017Z5 | B17: =TEST_DATA!B17 -> Sep-2017 | C17: =TEST_DATA!C17 -> 43393 | D17: =TEST_DATA!D17 -> NIL | E17: =TEST_DATA!E17 -> 1556 | F17: =MIN(E17*1700,10000) -> 10000 | G17: =_xludf.MINIFS(CBIC_Late_Fee_Relief_Windows_1!$I$17:$I$100,CBIC_Late_Fee_Relief_Windows_1!$D$17:$D$100,"<="&B17,CBIC_Late_Fee_Relief_Windows_1!$E$17:$E$100,">="&B17,CBIC_Late_Fee_Relief_Windows_1!$F$17:$F$100,"<="&C17,CBIC_Late_Fee_Relief_Windows_1!$G$17:$G$100,">="&C17,CBIC_Late_Fee_Relief_Windows_1!$H$17:$H$100,D17) -> #NAME? | H17: =MIN(F17,G17) -> #NAME? | I17: =INDEX(CBIC_Late_Fee_Relief_Windows_1!$B$17:$B$100,MATCH(G17,CBIC_Late_Fee_Relief_Windows_1!$I$17:$I$100,0)) -> #NAME?
A18: =TEST_DATA!A18 -> 27AAAAA0018Z5 | B18: =TEST_DATA!B18 -> Mar-2018 | C18: =TEST_DATA!C18 -> 43845 | D18: =TEST_DATA!D18 -> NON-NIL | E18: =TEST_DATA!E18 -> 666 | F18: =MIN(E18*1800,10000) -> 10000 | G18: =_xludf.MINIFS(CBIC_Late_Fee_Relief_Windows_1!$I$18:$I$100,CBIC_Late_Fee_Relief_Windows_1!$D$18:$D$100,"<="&B18,CBIC_Late_Fee_Relief_Windows_1!$E$18:$E$100,">="&B18,CBIC_Late_Fee_Relief_Windows_1!$F$18:$F$100,"<="&C18,CBIC_Late_Fee_Relief_Windows_1!$G$18:$G$100,">="&C18,CBIC_Late_Fee_Relief_Windows_1!$H$18:$H$100,D18) -> #NAME? | H18: =MIN(F18,G18) -> #NAME? | I18: =INDEX(CBIC_Late_Fee_Relief_Windows_1!$B$18:$B$100,MATCH(G18,CBIC_Late_Fee_Relief_Windows_1!$I$18:$I$100,0)) -> #NAME?
A19: =TEST_DATA!A19 -> 27AAAAA0019Z5 | B19: =TEST_DATA!B19 -> Jun-2018 | C19: =TEST_DATA!C19 -> 43644 | D19: =TEST_DATA!D19 -> NIL | E19: =TEST_DATA!E19 -> 2745 | F19: =MIN(E19*1900,10000) -> 10000 | G19: =_xludf.MINIFS(CBIC_Late_Fee_Relief_Windows_1!$I$19:$I$100,CBIC_Late_Fee_Relief_Windows_1!$D$19:$D$100,"<="&B19,CBIC_Late_Fee_Relief_Windows_1!$E$19:$E$100,">="&B19,CBIC_Late_Fee_Relief_Windows_1!$F$19:$F$100,"<="&C19,CBIC_Late_Fee_Relief_Windows_1!$G$19:$G$100,">="&C19,CBIC_Late_Fee_Relief_Windows_1!$H$19:$H$100,D19) -> #NAME? | H19: =MIN(F19,G19) -> #NAME? | I19: =INDEX(CBIC_Late_Fee_Relief_Windows_1!$B$19:$B$100,MATCH(G19,CBIC_Late_Fee_Relief_Windows_1!$I$19:$I$100,0)) -> #NAME?
A20: =TEST_DATA!A20 -> 27AAAAA0020Z5 | B20: =TEST_DATA!B20 -> Mar-2018 | C20: =TEST_DATA!C20 -> 44354 | D20: =TEST_DATA!D20 -> NIL | E20: =TEST_DATA!E20 -> 2495 | F20: =MIN(E20*2000,10000) -> 10000 | G20: =_xludf.MINIFS(CBIC_Late_Fee_Relief_Windows_1!$I$20:$I$100,CBIC_Late_Fee_Relief_Windows_1!$D$20:$D$100,"<="&B20,CBIC_Late_Fee_Relief_Windows_1!$E$20:$E$100,">="&B20,CBIC_Late_Fee_Relief_Windows_1!$F$20:$F$100,"<="&C20,CBIC_Late_Fee_Relief_Windows_1!$G$20:$G$100,">="&C20,CBIC_Late_Fee_Relief_Windows_1!$H$20:$H$100,D20) -> #NAME? | H20: =MIN(F20,G20) -> #NAME? | I20: =INDEX(CBIC_Late_Fee_Relief_Windows_1!$B$20:$B$100,MATCH(G20,CBIC_Late_Fee_Relief_Windows_1!$I$20:$I$100,0)) -> #NAME?
A21: =TEST_DATA!A21 -> 27AAAAA0021Z5 | B21: =TEST_DATA!B21 -> May-2020 | C21: =TEST_DATA!C21 -> 44181 | D21: =TEST_DATA!D21 -> NIL | E21: =TEST_DATA!E21 -> 669 | F21: =MIN(E21*2100,10000) -> 10000 | G21: =_xludf.MINIFS(CBIC_Late_Fee_Relief_Windows_1!$I$21:$I$100,CBIC_Late_Fee_Relief_Windows_1!$D$21:$D$100,"<="&B21,CBIC_Late_Fee_Relief_Windows_1!$E$21:$E$100,">="&B21,CBIC_Late_Fee_Relief_Windows_1!$F$21:$F$100,"<="&C21,CBIC_Late_Fee_Relief_Windows_1!$G$21:$G$100,">="&C21,CBIC_Late_Fee_Relief_Windows_1!$H$21:$H$100,D21) -> #NAME? | H21: =MIN(F21,G21) -> #NAME? | I21: =INDEX(CBIC_Late_Fee_Relief_Windows_1!$B$21:$B$100,MATCH(G21,CBIC_Late_Fee_Relief_Windows_1!$I$21:$I$100,0)) -> #NAME?
A22: =TEST_DATA!A22 -> 27AAAAA0022Z5 | B22: =TEST_DATA!B22 -> Sep-2018 | C22: =TEST_DATA!C22 -> 43694 | D22: =TEST_DATA!D22 -> NON-NIL | E22: =TEST_DATA!E22 -> 2621 | F22: =MIN(E22*2200,10000) -> 10000 | G22: =_xludf.MINIFS(CBIC_Late_Fee_Relief_Windows_1!$I$22:$I$100,CBIC_Late_Fee_Relief_Windows_1!$D$22:$D$100,"<="&B22,CBIC_Late_Fee_Relief_Windows_1!$E$22:$E$100,">="&B22,CBIC_Late_Fee_Relief_Windows_1!$F$22:$F$100,"<="&C22,CBIC_Late_Fee_Relief_Windows_1!$G$22:$G$100,">="&C22,CBIC_Late_Fee_Relief_Windows_1!$H$22:$H$100,D22) -> #NAME? | H22: =MIN(F22,G22) -> #NAME? | I22: =INDEX(CBIC_Late_Fee_Relief_Windows_1!$B$22:$B$100,MATCH(G22,CBIC_Late_Fee_Relief_Windows_1!$I$22:$I$100,0)) -> #NAME?
A23: =TEST_DATA!A23 -> 27AAAAA0023Z5 | B23: =TEST_DATA!B23 -> Jul-2020 | C23: =TEST_DATA!C23 -> 44280 | D23: =TEST_DATA!D23 -> NON-NIL | E23: =TEST_DATA!E23 -> 229 | F23: =MIN(E23*2300,10000) -> 10000 | G23: =_xludf.MINIFS(CBIC_Late_Fee_Relief_Windows_1!$I$23:$I$100,CBIC_Late_Fee_Relief_Windows_1!$D$23:$D$100,"<="&B23,CBIC_Late_Fee_Relief_Windows_1!$E$23:$E$100,">="&B23,CBIC_Late_Fee_Relief_Windows_1!$F$23:$F$100,"<="&C23,CBIC_Late_Fee_Relief_Windows_1!$G$23:$G$100,">="&C23,CBIC_Late_Fee_Relief_Windows_1!$H$23:$H$100,D23) -> #NAME? | H23: =MIN(F23,G23) -> #NAME? | I23: =INDEX(CBIC_Late_Fee_Relief_Windows_1!$B$23:$B$100,MATCH(G23,CBIC_Late_Fee_Relief_Windows_1!$I$23:$I$100,0)) -> #NAME?
A24: =TEST_DATA!A24 -> 27AAAAA0024Z5 | B24: =TEST_DATA!B24 -> Feb-2018 | C24: =TEST_DATA!C24 -> 42982 | D24: =TEST_DATA!D24 -> NON-NIL | E24: =TEST_DATA!E24 -> 1643 | F24: =MIN(E24*2400,10000) -> 10000 | G24: =_xludf.MINIFS(CBIC_Late_Fee_Relief_Windows_1!$I$24:$I$100,CBIC_Late_Fee_Relief_Windows_1!$D$24:$D$100,"<="&B24,CBIC_Late_Fee_Relief_Windows_1!$E$24:$E$100,">="&B24,CBIC_Late_Fee_Relief_Windows_1!$F$24:$F$100,"<="&C24,CBIC_Late_Fee_Relief_Windows_1!$G$24:$G$100,">="&C24,CBIC_Late_Fee_Relief_Windows_1!$H$24:$H$100,D24) -> #NAME? | H24: =MIN(F24,G24) -> #NAME? | I24: =INDEX(CBIC_Late_Fee_Relief_Windows_1!$B$24:$B$100,MATCH(G24,CBIC_Late_Fee_Relief_Windows_1!$I$24:$I$100,0)) -> #NAME?
A25: =TEST_DATA!A25 -> 27AAAAA0025Z5 | B25: =TEST_DATA!B25 -> Mar-2018 | C25: =TEST_DATA!C25 -> 43052 | D25: =TEST_DATA!D25 -> NIL | E25: =TEST_DATA!E25 -> 2323 | F25: =MIN(E25*2500,10000) -> 10000 | G25: =_xludf.MINIFS(CBIC_Late_Fee_Relief_Windows_1!$I$25:$I$100,CBIC_Late_Fee_Relief_Windows_1!$D$25:$D$100,"<="&B25,CBIC_Late_Fee_Relief_Windows_1!$E$25:$E$100,">="&B25,CBIC_Late_Fee_Relief_Windows_1!$F$25:$F$100,"<="&C25,CBIC_Late_Fee_Relief_Windows_1!$G$25:$G$100,">="&C25,CBIC_Late_Fee_Relief_Windows_1!$H$25:$H$100,D25) -> #NAME? | H25: =MIN(F25,G25) -> #NAME? | I25: =INDEX(CBIC_Late_Fee_Relief_Windows_1!$B$25:$B$100,MATCH(G25,CBIC_Late_Fee_Relief_Windows_1!$I$25:$I$100,0)) -> #NAME?
A26: =TEST_DATA!A26 -> 27AAAAA0026Z5 | B26: =TEST_DATA!B26 -> Dec-2024 | C26: =TEST_DATA!C26 -> 44754 | D26: =TEST_DATA!D26 -> NIL | E26: =TEST_DATA!E26 -> 2684 | F26: =MIN(E26*2600,10000) -> 10000 | G26: =_xludf.MINIFS(CBIC_Late_Fee_Relief_Windows_1!$I$26:$I$100,CBIC_Late_Fee_Relief_Windows_1!$D$26:$D$100,"<="&B26,CBIC_Late_Fee_Relief_Windows_1!$E$26:$E$100,">="&B26,CBIC_Late_Fee_Relief_Windows_1!$F$26:$F$100,"<="&C26,CBIC_Late_Fee_Relief_Windows_1!$G$26:$G$100,">="&C26,CBIC_Late_Fee_Relief_Windows_1!$H$26:$H$100,D26) -> #NAME? | H26: =MIN(F26,G26) -> #NAME? | I26: =INDEX(CBIC_Late_Fee_Relief_Windows_1!$B$26:$B$100,MATCH(G26,CBIC_Late_Fee_Relief_Windows_1!$I$26:$I$100,0)) -> #NAME?
A27: =TEST_DATA!A27 -> 27AAAAA0027Z5 | B27: =TEST_DATA!B27 -> Jan-2019 | C27: =TEST_DATA!C27 -> 45086 | D27: =TEST_DATA!D27 -> NON-NIL | E27: =TEST_DATA!E27 -> 585 | F27: =MIN(E27*2700,10000) -> 10000 | G27: =_xludf.MINIFS(CBIC_Late_Fee_Relief_Windows_1!$I$27:$I$100,CBIC_Late_Fee_Relief_Windows_1!$D$27:$D$100,"<="&B27,CBIC_Late_Fee_Relief_Windows_1!$E$27:$E$100,">="&B27,CBIC_Late_Fee_Relief_Windows_1!$F$27:$F$100,"<="&C27,CBIC_Late_Fee_Relief_Windows_1!$G$27:$G$100,">="&C27,CBIC_Late_Fee_Relief_Windows_1!$H$27:$H$100,D27) -> #NAME? | H27: =MIN(F27,G27) -> #NAME? | I27: =INDEX(CBIC_Late_Fee_Relief_Windows_1!$B$27:$B$100,MATCH(G27,CBIC_Late_Fee_Relief_Windows_1!$I$27:$I$100,0)) -> #NAME?
A28: =TEST_DATA!A28 -> 27AAAAA0028Z5 | B28: =TEST_DATA!B28 -> Mar-2018 | C28: =TEST_DATA!C28 -> 43202 | D28: =TEST_DATA!D28 -> NIL | E28: =TEST_DATA!E28 -> 2299 | F28: =MIN(E28*2800,10000) -> 10000 | G28: =_xludf.MINIFS(CBIC_Late_Fee_Relief_Windows_1!$I$28:$I$100,CBIC_Late_Fee_Relief_Windows_1!$D$28:$D$100,"<="&B28,CBIC_Late_Fee_Relief_Windows_1!$E$28:$E$100,">="&B28,CBIC_Late_Fee_Relief_Windows_1!$F$28:$F$100,"<="&C28,CBIC_Late_Fee_Relief_Windows_1!$G$28:$G$100,">="&C28,CBIC_Late_Fee_Relief_Windows_1!$H$28:$H$100,D28) -> #NAME? | H28: =MIN(F28,G28) -> #NAME? | I28: =INDEX(CBIC_Late_Fee_Relief_Windows_1!$B$28:$B$100,MATCH(G28,CBIC_Late_Fee_Relief_Windows_1!$I$28:$I$100,0)) -> #NAME?
A29: =TEST_DATA!A29 -> 27AAAAA0029Z5 | B29: =TEST_DATA!B29 -> Dec-2019 | C29: =TEST_DATA!C29 -> 44542 | D29: =TEST_DATA!D29 -> NON-NIL | E29: =TEST_DATA!E29 -> 2390 | F29: =MIN(E29*2900,10000) -> 10000 | G29: =_xludf.MINIFS(CBIC_Late_Fee_Relief_Windows_1!$I$29:$I$100,CBIC_Late_Fee_Relief_Windows_1!$D$29:$D$100,"<="&B29,CBIC_Late_Fee_Relief_Windows_1!$E$29:$E$100,">="&B29,CBIC_Late_Fee_Relief_Windows_1!$F$29:$F$100,"<="&C29,CBIC_Late_Fee_Relief_Windows_1!$G$29:$G$100,">="&C29,CBIC_Late_Fee_Relief_Windows_1!$H$29:$H$100,D29) -> #NAME? | H29: =MIN(F29,G29) -> #NAME? | I29: =INDEX(CBIC_Late_Fee_Relief_Windows_1!$B$29:$B$100,MATCH(G29,CBIC_Late_Fee_Relief_Windows_1!$I$29:$I$100,0)) -> #NAME?
A30: =TEST_DATA!A30 -> 27AAAAA0030Z5 | B30: =TEST_DATA!B30 -> Jul-2018 | C30: =TEST_DATA!C30 -> 43658 | D30: =TEST_DATA!D30 -> NIL | E30: =TEST_DATA!E30 -> 566 | F30: =MIN(E30*3000,10000) -> 10000 | G30: =_xludf.MINIFS(CBIC_Late_Fee_Relief_Windows_1!$I$30:$I$100,CBIC_Late_Fee_Relief_Windows_1!$D$30:$D$100,"<="&B30,CBIC_Late_Fee_Relief_Windows_1!$E$30:$E$100,">="&B30,CBIC_Late_Fee_Relief_Windows_1!$F$30:$F$100,"<="&C30,CBIC_Late_Fee_Relief_Windows_1!$G$30:$G$100,">="&C30,CBIC_Late_Fee_Relief_Windows_1!$H$30:$H$100,D30) -> #NAME? | H30: =MIN(F30,G30) -> #NAME? | I30: =INDEX(CBIC_Late_Fee_Relief_Windows_1!$B$30:$B$100,MATCH(G30,CBIC_Late_Fee_Relief_Windows_1!$I$30:$I$100,0)) -> #NAME?
A31: =TEST_DATA!A31 -> 27AAAAA0031Z5 | B31: =TEST_DATA!B31 -> Jun-2019 | C31: =TEST_DATA!C31 -> 45487 | D31: =TEST_DATA!D31 -> NIL | E31: =TEST_DATA!E31 -> 192 | F31: =MIN(E31*3100,10000) -> 10000 | G31: =_xludf.MINIFS(CBIC_Late_Fee_Relief_Windows_1!$I$31:$I$100,CBIC_Late_Fee_Relief_Windows_1!$D$31:$D$100,"<="&B31,CBIC_Late_Fee_Relief_Windows_1!$E$31:$E$100,">="&B31,CBIC_Late_Fee_Relief_Windows_1!$F$31:$F$100,"<="&C31,CBIC_Late_Fee_Relief_Windows_1!$G$31:$G$100,">="&C31,CBIC_Late_Fee_Relief_Windows_1!$H$31:$H$100,D31) -> #NAME? | H31: =MIN(F31,G31) -> #NAME? | I31: =INDEX(CBIC_Late_Fee_Relief_Windows_1!$B$31:$B$100,MATCH(G31,CBIC_Late_Fee_Relief_Windows_1!$I$31:$I$100,0)) -> #NAME?
A32: =TEST_DATA!A32 -> 27AAAAA0032Z5 | B32: =TEST_DATA!B32 -> Mar-2023 | C32: =TEST_DATA!C32 -> 43915 | D32: =TEST_DATA!D32 -> NIL | E32: =TEST_DATA!E32 -> 2570 | F32: =MIN(E32*3200,10000) -> 10000 | G32: =_xludf.MINIFS(CBIC_Late_Fee_Relief_Windows_1!$I$32:$I$100,CBIC_Late_Fee_Relief_Windows_1!$D$32:$D$100,"<="&B32,CBIC_Late_Fee_Relief_Windows_1!$E$32:$E$100,">="&B32,CBIC_Late_Fee_Relief_Windows_1!$F$32:$F$100,"<="&C32,CBIC_Late_Fee_Relief_Windows_1!$G$32:$G$100,">="&C32,CBIC_Late_Fee_Relief_Windows_1!$H$32:$H$100,D32) -> #NAME? | H32: =MIN(F32,G32) -> #NAME? | I32: =INDEX(CBIC_Late_Fee_Relief_Windows_1!$B$32:$B$100,MATCH(G32,CBIC_Late_Fee_Relief_Windows_1!$I$32:$I$100,0)) -> #NAME?
A33: =TEST_DATA!A33 -> 27AAAAA0033Z5 | B33: =TEST_DATA!B33 -> Dec-2017 | C33: =TEST_DATA!C33 -> 44539 | D33: =TEST_DATA!D33 -> NON-NIL | E33: =TEST_DATA!E33 -> 2442 | F33: =MIN(E33*3300,10000) -> 10000 | G33: =_xludf.MINIFS(CBIC_Late_Fee_Relief_Windows_1!$I$33:$I$100,CBIC_Late_Fee_Relief_Windows_1!$D$33:$D$100,"<="&B33,CBIC_Late_Fee_Relief_Windows_1!$E$33:$E$100,">="&B33,CBIC_Late_Fee_Relief_Windows_1!$F$33:$F$100,"<="&C33,CBIC_Late_Fee_Relief_Windows_1!$G$33:$G$100,">="&C33,CBIC_Late_Fee_Relief_Windows_1!$H$33:$H$100,D33) -> #NAME? | H33: =MIN(F33,G33) -> #NAME? | I33: =INDEX(CBIC_Late_Fee_Relief_Windows_1!$B$33:$B$100,MATCH(G33,CBIC_Late_Fee_Relief_Windows_1!$I$33:$I$100,0)) -> #NAME?
A34: =TEST_DATA!A34 -> 27AAAAA0034Z5 | B34: =TEST_DATA!B34 -> Sep-2017 | C34: =TEST_DATA!C34 -> 43705 | D34: =TEST_DATA!D34 -> NON-NIL | E34: =TEST_DATA!E34 -> 2440 | F34: =MIN(E34*3400,10000) -> 10000 | G34: =_xludf.MINIFS(CBIC_Late_Fee_Relief_Windows_1!$I$34:$I$100,CBIC_Late_Fee_Relief_Windows_1!$D$34:$D$100,"<="&B34,CBIC_Late_Fee_Relief_Windows_1!$E$34:$E$100,">="&B34,CBIC_Late_Fee_Relief_Windows_1!$F$34:$F$100,"<="&C34,CBIC_Late_Fee_Relief_Windows_1!$G$34:$G$100,">="&C34,CBIC_Late_Fee_Relief_Windows_1!$H$34:$H$100,D34) -> #NAME? | H34: =MIN(F34,G34) -> #NAME? | I34: =INDEX(CBIC_Late_Fee_Relief_Windows_1!$B$34:$B$100,MATCH(G34,CBIC_Late_Fee_Relief_Windows_1!$I$34:$I$100,0)) -> #NAME?
A35: =TEST_DATA!A35 -> 27AAAAA0035Z5 | B35: =TEST_DATA!B35 -> Sep-2018 | C35: =TEST_DATA!C35 -> 44000 | D35: =TEST_DATA!D35 -> NON-NIL | E35: =TEST_DATA!E35 -> 2266 | F35: =MIN(E35*3500,10000) -> 10000 | G35: =_xludf.MINIFS(CBIC_Late_Fee_Relief_Windows_1!$I$35:$I$100,CBIC_Late_Fee_Relief_Windows_1!$D$35:$D$100,"<="&B35,CBIC_Late_Fee_Relief_Windows_1!$E$35:$E$100,">="&B35,CBIC_Late_Fee_Relief_Windows_1!$F$35:$F$100,"<="&C35,CBIC_Late_Fee_Relief_Windows_1!$G$35:$G$100,">="&C35,CBIC_Late_Fee_Relief_Windows_1!$H$35:$H$100,D35) -> #NAME? | H35: =MIN(F35,G35) -> #NAME? | I35: =INDEX(CBIC_Late_Fee_Relief_Windows_1!$B$35:$B$100,MATCH(G35,CBIC_Late_Fee_Relief_Windows_1!$I$35:$I$100,0)) -> #NAME?
A36: =TEST_DATA!A36 -> 27AAAAA0036Z5 | B36: =TEST_DATA!B36 -> Mar-2023 | C36: =TEST_DATA!C36 -> 43513 | D36: =TEST_DATA!D36 -> NIL | E36: =TEST_DATA!E36 -> 2792 | F36: =MIN(E36*3600,10000) -> 10000 | G36: =_xludf.MINIFS(CBIC_Late_Fee_Relief_Windows_1!$I$36:$I$100,CBIC_Late_Fee_Relief_Windows_1!$D$36:$D$100,"<="&B36,CBIC_Late_Fee_Relief_Windows_1!$E$36:$E$100,">="&B36,CBIC_Late_Fee_Relief_Windows_1!$F$36:$F$100,"<="&C36,CBIC_Late_Fee_Relief_Windows_1!$G$36:$G$100,">="&C36,CBIC_Late_Fee_Relief_Windows_1!$H$36:$H$100,D36) -> #NAME? | H36: =MIN(F36,G36) -> #NAME? | I36: =INDEX(CBIC_Late_Fee_Relief_Windows_1!$B$36:$B$100,MATCH(G36,CBIC_Late_Fee_Relief_Windows_1!$I$36:$I$100,0)) -> #NAME?
A37: =TEST_DATA!A37 -> 27AAAAA0037Z5 | B37: =TEST_DATA!B37 -> Dec-2024 | C37: =TEST_DATA!C37 -> 45665 | D37: =TEST_DATA!D37 -> NON-NIL | E37: =TEST_DATA!E37 -> 2625 | F37: =MIN(E37*3700,10000) -> 10000 | G37: =_xludf.MINIFS(CBIC_Late_Fee_Relief_Windows_1!$I$37:$I$100,CBIC_Late_Fee_Relief_Windows_1!$D$37:$D$100,"<="&B37,CBIC_Late_Fee_Relief_Windows_1!$E$37:$E$100,">="&B37,CBIC_Late_Fee_Relief_Windows_1!$F$37:$F$100,"<="&C37,CBIC_Late_Fee_Relief_Windows_1!$G$37:$G$100,">="&C37,CBIC_Late_Fee_Relief_Windows_1!$H$37:$H$100,D37) -> #NAME? | H37: =MIN(F37,G37) -> #NAME? | I37: =INDEX(CBIC_Late_Fee_Relief_Windows_1!$B$37:$B$100,MATCH(G37,CBIC_Late_Fee_Relief_Windows_1!$I$37:$I$100,0)) -> #NAME?
A38: =TEST_DATA!A38 -> 27AAAAA0038Z5 | B38: =TEST_DATA!B38 -> May-2018 | C38: =TEST_DATA!C38 -> 43145 | D38: =TEST_DATA!D38 -> NON-NIL | E38: =TEST_DATA!E38 -> 1780 | F38: =MIN(E38*3800,10000) -> 10000 | G38: =_xludf.MINIFS(CBIC_Late_Fee_Relief_Windows_1!$I$38:$I$100,CBIC_Late_Fee_Relief_Windows_1!$D$38:$D$100,"<="&B38,CBIC_Late_Fee_Relief_Windows_1!$E$38:$E$100,">="&B38,CBIC_Late_Fee_Relief_Windows_1!$F$38:$F$100,"<="&C38,CBIC_Late_Fee_Relief_Windows_1!$G$38:$G$100,">="&C38,CBIC_Late_Fee_Relief_Windows_1!$H$38:$H$100,D38) -> #NAME? | H38: =MIN(F38,G38) -> #NAME? | I38: =INDEX(CBIC_Late_Fee_Relief_Windows_1!$B$38:$B$100,MATCH(G38,CBIC_Late_Fee_Relief_Windows_1!$I$38:$I$100,0)) -> #NAME?
A39: =TEST_DATA!A39 -> 27AAAAA0039Z5 | B39: =TEST_DATA!B39 -> Dec-2017 | C39: =TEST_DATA!C39 -> 43846 | D39: =TEST_DATA!D39 -> NIL | E39: =TEST_DATA!E39 -> 2957 | F39: =MIN(E39*3900,10000) -> 10000 | G39: =_xludf.MINIFS(CBIC_Late_Fee_Relief_Windows_1!$I$39:$I$100,CBIC_Late_Fee_Relief_Windows_1!$D$39:$D$100,"<="&B39,CBIC_Late_Fee_Relief_Windows_1!$E$39:$E$100,">="&B39,CBIC_Late_Fee_Relief_Windows_1!$F$39:$F$100,"<="&C39,CBIC_Late_Fee_Relief_Windows_1!$G$39:$G$100,">="&C39,CBIC_Late_Fee_Relief_Windows_1!$H$39:$H$100,D39) -> #NAME? | H39: =MIN(F39,G39) -> #NAME? | I39: =INDEX(CBIC_Late_Fee_Relief_Windows_1!$B$39:$B$100,MATCH(G39,CBIC_Late_Fee_Relief_Windows_1!$I$39:$I$100,0)) -> #NAME?
A40: =TEST_DATA!A40 -> 27AAAAA0040Z5 | B40: =TEST_DATA!B40 -> Dec-2024 | C40: =TEST_DATA!C40 -> 44544 | D40: =TEST_DATA!D40 -> NIL | E40: =TEST_DATA!E40 -> 2079 | F40: =MIN(E40*4000,10000) -> 10000 | G40: =_xludf.MINIFS(CBIC_Late_Fee_Relief_Windows_1!$I$40:$I$100,CBIC_Late_Fee_Relief_Windows_1!$D$40:$D$100,"<="&B40,CBIC_Late_Fee_Relief_Windows_1!$E$40:$E$100,">="&B40,CBIC_Late_Fee_Relief_Windows_1!$F$40:$F$100,"<="&C40,CBIC_Late_Fee_Relief_Windows_1!$G$40:$G$100,">="&C40,CBIC_Late_Fee_Relief_Windows_1!$H$40:$H$100,D40) -> #NAME? | H40: =MIN(F40,G40) -> #NAME? | I40: =INDEX(CBIC_Late_Fee_Relief_Windows_1!$B$40:$B$100,MATCH(G40,CBIC_Late_Fee_Relief_Windows_1!$I$40:$I$100,0)) -> #NAME?
...

Sheet TEST_DATA
A1: GSTIN | B1: Tax Period | C1: Filing Date | D1: Return Type | E1: Delay Days
A2: 27AAAAA0002Z5 | B2: May-2020 | C2: 44059 | D2: NIL | E2: 1126
A3: 27AAAAA0003Z5 | B3: Feb-2018 | C3: 43374 | D3: NIL | E3: 419
A4: 27AAAAA0004Z5 | B4: Jun-2020 | C4: 44009 | D4: NON-NIL | E4: 130
A5: 27AAAAA0005Z5 | B5: Jul-2017 | C5: 43108 | D5: NIL | E5: 952
A6: 27AAAAA0006Z5 | B6: Jun-2019 | C6: 43574 | D6: NIL | E6: 2932
A7: 27AAAAA0007Z5 | B7: May-2020 | C7: 44690 | D7: NIL | E7: 1839
A8: 27AAAAA0008Z5 | B8: Mar-2020 | C8: 44400 | D8: NIL | E8: 653
A9: 27AAAAA0009Z5 | B9: Jul-2020 | C9: 44696 | D9: NON-NIL | E9: 1138
A10: 27AAAAA0010Z5 | B10: Nov-2017 | C10: 43357 | D10: NON-NIL | E10: 418
A11: 27AAAAA0011Z5 | B11: Sep-2017 | C11: 43695 | D11: NIL | E11: 1470
A12: 27AAAAA0012Z5 | B12: Mar-2023 | C12: 44874 | D12: NON-NIL | E12: 177
A13: 27AAAAA0013Z5 | B13: Jan-2021 | C13: 45347 | D13: NIL | E13: 1550
... A15001: 27AAAAA15001Z5 | B15001: Apr-2021 | C15001: 44617 | D15001: NON-NIL | E15001: 2649

Sheet ASSERTIONS
A1: Assertion | B1: Formula | C1: Result
A2: Final Late Fee <= 10000 | B2: =COUNTIF(CALCULATOR!H2:H15001,">10000") -> 0 | C2: =IF(B2=0,"PASS","FAIL") -> PASS
A3: No blank Final Late Fee | B3: =COUNTBLANK(CALCULATOR!H2:H15001) -> 13002 | C3: =IF(B3=0,"PASS","FAIL") -> FAIL
A4: Normal Late Fee >= Final Late Fee | B4: =COUNTIF(CALCULATOR!H2:H15001,">"&CALCULATOR!F2:F15001) -> 0 | C4: =IF(B4=0,"PASS","FAIL") -> PASS
