Workbook

Sheet CBIC_Late_Fee_Relief_Windows_3B
A1: Relief Window ID | B1: Notification No | C1: Notification Date | D1: Relief Category | E1: Tax Period From | F1: Tax Period To | G1: Filing Date From | H1: Filing Date To | I1: Return Type | J1: Turnover Slab | K1: Max Late Fee Allowed | L1: Late Fee Nature | M1: SCN Defence Text | N1: Judicial Sensitivity | O1: Window Priority
A2: NIL_STRUCT_ALL | B2: Sec 47 CGST Act | C2: 01-07-2017 | D2: Structural | E2: Jul-2017 | F2: Jan-2026 | G2: 01-07-2017 | H2: 31-12-2099 | I2: NIL | J2: ALL | K2: 500 | L2: Cap | M2: Late fee restricted to ₹500 for NIL return under Section 47. | N2: Low | O2: 5
A3: C19_Mar-2020_NIL | B3: 52/2020-CT | C3: 24-06-2020 | D3: Cap | E3: Mar-2020 | F3: Mar-2020 | G3: 01-03-2020 | H3: 31-12-2020 | I3: NIL | J3: ALL | K3: 0 | L3: Waiver | M3: Late fee waived for NIL return under COVID-19 relief (52/2020-CT). | N3: Medium | O3: 6
A4: C19_Mar-2020_NON | B4: 52/2020-CT | C4: 24-06-2020 | D4: Cap | E4: Mar-2020 | F4: Mar-2020 | G4: 01-03-2020 | H4: 31-12-2020 | I4: NON-NIL | J4: ALL | K4: 1000 | L4: Cap | M4: Late fee capped at ₹1,000 under COVID-19 relief (52/2020-CT). | N4: Medium | O4: 6
A5: C19_Apr-2020_NIL | B5: 52/2020-CT | C5: 24-06-2020 | D5: Cap | E5: Apr-2020 | F5: Apr-2020 | G5: 01-03-2020 | H5: 31-12-2020 | I5: NIL | J5: ALL | K5: 0 | L5: Waiver | M5: Late fee waived for NIL return under COVID-19 relief (52/2020-CT). | N5: Medium | O5: 6
A6: C19_Apr-2020_NON | B6: 52/2020-CT | C6: 24-06-2020 | D6: Cap | E6: Apr-2020 | F6: Apr-2020 | G6: 01-03-2020 | H6: 31-12-2020 | I6: NON-NIL | J6: ALL | K6: 1000 | L6: Cap | M6: Late fee capped at ₹1,000 under COVID-19 relief (52/2020-CT). | N6: Medium | O6: 6
A7: C19_May-2020_NIL | B7: 52/2020-CT | C7: 24-06-2020 | D7: Cap | E7: May-2020 | F7: May-2020 | G7: 01-03-2020 | H7: 31-12-2020 | I7: NIL | J7: ALL | K7: 0 | L7: Waiver | M7: Late fee waived for NIL return under COVID-19 relief (52/2020-CT). | N7: Medium | O7: 6
A8: C19_May-2020_NON | B8: 52/2020-CT | C8: 24-06-2020 | D8: Cap | E8: May-2020 | F8: May-2020 | G8: 01-03-2020 | H8: 31-12-2020 | I8: NON-NIL | J8: ALL | K8: 1000 | L8: Cap | M8: Late fee capped at ₹1,000 under COVID-19 relief (52/2020-CT). | N8: Medium | O8: 6
A9: C19_Jun-2020_NIL | B9: 52/2020-CT | C9: 24-06-2020 | D9: Cap | E9: Jun-2020 | F9: Jun-2020 | G9: 01-03-2020 | H9: 31-12-2020 | I9: NIL | J9: ALL | K9: 0 | L9: Waiver | M9: Late fee waived for NIL return under COVID-19 relief (52/2020-CT). | N9: Medium | O9: 6
A10: C19_Jun-2020_NON | B10: 52/2020-CT | C10: 24-06-2020 | D10: Cap | E10: Jun-2020 | F10: Jun-2020 | G10: 01-03-2020 | H10: 31-12-2020 | I10: NON-NIL | J10: ALL | K10: 1000 | L10: Cap | M10: Late fee capped at ₹1,000 under COVID-19 relief (52/2020-CT). | N10: Medium | O10: 6
A11: C19_Jul-2020_NIL | B11: 52/2020-CT | C11: 24-06-2020 | D11: Cap | E11: Jul-2020 | F11: Jul-2020 | G11: 01-03-2020 | H11: 31-12-2020 | I11: NIL | J11: ALL | K11: 0 | L11: Waiver | M11: Late fee waived for NIL return under COVID-19 relief (52/2020-CT). | N11: Medium | O11: 6
A12: C19_Jul-2020_NON | B12: 52/2020-CT | C12: 24-06-2020 | D12: Cap | E12: Jul-2020 | F12: Jul-2020 | G12: 01-03-2020 | H12: 31-12-2020 | I12: NON-NIL | J12: ALL | K12: 1000 | L12: Cap | M12: Late fee capped at ₹1,000 under COVID-19 relief (52/2020-CT). | N12: Medium | O12: 6
A13: AMN_2018_FULL | B13: 76/2018-CT | C13: 31-12-2018 | D13: Amnesty | E13: Jul-2017 | F13: Sep-2018 | G13: 22-12-2018 | H13: 31-03-2019 | I13: ALL | J13: ALL | K13: 0 | L13: Waiver | M13: Late fee fully waived under Notification 76/2018-CT. | N13: Low | O13: 1
... A293: Apr-2021_LF06_LARGE | B293: 33/2021-CT | C293: 29-08-2021 | D293: Amnesty | E293: Apr-2021 | F293: Apr-2021 | G293: 01-09-2021 | H293: 30-11-2021 | I293: NON-NIL | J293: >5Cr | K293: 5000 | L293: Cap | M293: Late fee capped at ₹5,000 under extended amnesty (33/2021-CT). | N293: Low | O293: 1

Sheet Late_Fee_Calculator_3B
A1: GSTIN | B1: Tax Period | C1: Filing Date | D1: Return Type | E1: Aggregate Turnover | F1: Turnover Slab | G1: Delay Days | H1: Normal Late Fee | I1: Allowed Max Late Fee (Auto) | J1: Final Late Fee (Auto) | K1: Waiver Amount (Auto)
A2: =TEST_DATA!A2 | B2: =TEST_DATA!B2 | C2: =TEST_DATA!C2 | D2: =TEST_DATA!D2 | E2: =TEST_DATA!E2 | F2: =MIN(E2*200,10000) | G2: =MINIFS(CBIC_Late_Fee_Relief_Windows_3B!$O$2:$O$100,CBIC_Late_Fee_Relief_Windows_3B!$D$2:$D$100,"<="&B2,CBIC_Late_Fee_Relief_Windows_3B!$E$2:$E$100,">="&B2,CBIC_Late_Fee_Relief_Windows_3B!$F$2:$F$100,"<="&C2,CBIC_Late_Fee_Relief_Windows_3B!$G$2:$G$100,">="&C2) | H2: =INDEX(CBIC_Late_Fee_Relief_Windows_3B!$I$2:$I$100,MATCH(G2,CBIC_Late_Fee_Relief_Windows_3B!$O$2:$O$100,0)) | I2: =MIN(F2,H2) | J2: =MIN(H2,I2) | K2: =H2-J2
A3: =TEST_DATA!A3 | B3: =TEST_DATA!B3 | C3: =TEST_DATA!C3 | D3: =TEST_DATA!D3 | E3: =TEST_DATA!E3 | F3: =MIN(E3*300,10000) | G3: =MINIFS(CBIC_Late_Fee_Relief_Windows_3B!$O$3:$O$100,CBIC_Late_Fee_Relief_Windows_3B!$D$3:$D$100,"<="&B3,CBIC_Late_Fee_Relief_Windows_3B!$E$3:$E$100,">="&B3,CBIC_Late_Fee_Relief_Windows_3B!$F$3:$F$100,"<="&C3,CBIC_Late_Fee_Relief_Windows_3B!$G$3:$G$100,">="&C3) | H3: =INDEX(CBIC_Late_Fee_Relief_Windows_3B!$I$3:$I$100,MATCH(G3,CBIC_Late_Fee_Relief_Windows_3B!$O$3:$O$100,0)) | I3: =MIN(F3,H3)
A4: =TEST_DATA!A4 | B4: =TEST_DATA!B4 | C4: =TEST_DATA!C4 | D4: =TEST_DATA!D4 | E4: =TEST_DATA!E4 | F4: =MIN(E4*400,10000) | G4: =MINIFS(CBIC_Late_Fee_Relief_Windows_3B!$O$4:$O$100,CBIC_Late_Fee_Relief_Windows_3B!$D$4:$D$100,"<="&B4,CBIC_Late_Fee_Relief_Windows_3B!$E$4:$E$100,">="&B4,CBIC_Late_Fee_Relief_Windows_3B!$F$4:$F$100,"<="&C4,CBIC_Late_Fee_Relief_Windows_3B!$G$4:$G$100,">="&C4) | H4: =INDEX(CBIC_Late_Fee_Relief_Windows_3B!$I$4:$I$100,MATCH(G4,CBIC_Late_Fee_Relief_Windows_3B!$O$4:$O$100,0)) | I4: =MIN(F4,H4)
A5: =TEST_DATA!A5 | B5: =TEST_DATA!B5 | C5: =TEST_DATA!C5 | D5: =TEST_DATA!D5 | E5: =TEST_DATA!E5 | F5: =MIN(E5*500,10000) | G5: =MINIFS(CBIC_Late_Fee_Relief_Windows_3B!$O$5:$O$100,CBIC_Late_Fee_Relief_Windows_3B!$D$5:$D$100,"<="&B5,CBIC_Late_Fee_Relief_Windows_3B!$E$5:$E$100,">="&B5,CBIC_Late_Fee_Relief_Windows_3B!$F$5:$F$100,"<="&C5,CBIC_Late_Fee_Relief_Windows_3B!$G$5:$G$100,">="&C5) | H5: =INDEX(CBIC_Late_Fee_Relief_Windows_3B!$I$5:$I$100,MATCH(G5,CBIC_Late_Fee_Relief_Windows_3B!$O$5:$O$100,0)) | I5: =MIN(F5,H5)
A6: =TEST_DATA!A6 | B6: =TEST_DATA!B6 | C6: =TEST_DATA!C6 | D6: =TEST_DATA!D6 | E6: =TEST_DATA!E6 | F6: =MIN(E6*600,10000) | G6: =MINIFS(CBIC_Late_Fee_Relief_Windows_3B!$O$6:$O$100,CBIC_Late_Fee_Relief_Windows_3B!$D$6:$D$100,"<="&B6,CBIC_Late_Fee_Relief_Windows_3B!$E$6:$E$100,">="&B6,CBIC_Late_Fee_Relief_Windows_3B!$F$6:$F$100,"<="&C6,CBIC_Late_Fee_Relief_Windows_3B!$G$6:$G$100,">="&C6) | H6: =INDEX(CBIC_Late_Fee_Relief_Windows_3B!$I$6:$I$100,MATCH(G6,CBIC_Late_Fee_Relief_Windows_3B!$O$6:$O$100,0)) | I6: =MIN(F6,H6)
A7: =TEST_DATA!A7 | B7: =TEST_DATA!B7 | C7: =TEST_DATA!C7 | D7: =TEST_DATA!D7 | E7: =TEST_DATA!E7 | F7: =MIN(E7*700,10000) | G7: =MINIFS(CBIC_Late_Fee_Relief_Windows_3B!$O$7:$O$100,CBIC_Late_Fee_Relief_Windows_3B!$D$7:$D$100,"<="&B7,CBIC_Late_Fee_Relief_Windows_3B!$E$7:$E$100,">="&B7,CBIC_Late_Fee_Relief_Windows_3B!$F$7:$F$100,"<="&C7,CBIC_Late_Fee_Relief_Windows_3B!$G$7:$G$100,">="&C7) | H7: =INDEX(CBIC_Late_Fee_Relief_Windows_3B!$I$7:$I$100,MATCH(G7,CBIC_Late_Fee_Relief_Windows_3B!$O$7:$O$100,0)) | I7: =MIN(F7,H7)
A8: =TEST_DATA!A8 | B8: =TEST_DATA!B8 | C8: =TEST_DATA!C8 | D8: =TEST_DATA!D8 | E8: =TEST_DATA!E8 | F8: =MIN(E8*800,10000) | G8: =MINIFS(CBIC_Late_Fee_Relief_Windows_3B!$O$8:$O$100,CBIC_Late_Fee_Relief_Windows_3B!$D$8:$D$100,"<="&B8,CBIC_Late_Fee_Relief_Windows_3B!$E$8:$E$100,">="&B8,CBIC_Late_Fee_Relief_Windows_3B!$F$8:$F$100,"<="&C8,CBIC_Late_Fee_Relief_Windows_3B!$G$8:$G$100,">="&C8) | H8: =INDEX(CBIC_Late_Fee_Relief_Windows_3B!$I$8:$I$100,MATCH(G8,CBIC_Late_Fee_Relief_Windows_3B!$O$8:$O$100,0)) | I8: =MIN(F8,H8)
A9: =TEST_DATA!A9 | B9: =TEST_DATA!B9 | C9: =TEST_DATA!C9 | D9: =TEST_DATA!D9 | E9: =TEST_DATA!E9 | F9: =MIN(E9*900,10000) | G9: =MINIFS(CBIC_Late_Fee_Relief_Windows_3B!$O$9:$O$100,CBIC_Late_Fee_Relief_Windows_3B!$D$9:$D$100,"<="&B9,CBIC_Late_Fee_Relief_Windows_3B!$E$9:$E$100,">="&B9,CBIC_Late_Fee_Relief_Windows_3B!$F$9:$F$100,"<="&C9,CBIC_Late_Fee_Relief_Windows_3B!$G$9:$G$100,">="&C9) | H9: =INDEX(CBIC_Late_Fee_Relief_Windows_3B!$I$9:$I$100,MATCH(G9,CBIC_Late_Fee_Relief_Windows_3B!$O$9:$O$100,0)) | I9: =MIN(F9,H9)
A10: =TEST_DATA!A10 | B10: =TEST_DATA!B10 | C10: =TEST_DATA!C10 | D10: =TEST_DATA!D10 | E10: =TEST_DATA!E10 | F10: =MIN(E10*1000,10000) | G10: =MINIFS(CBIC_Late_Fee_Relief_Windows_3B!$O$10:$O$100,CBIC_Late_Fee_Relief_Windows_3B!$D$10:$D$100,"<="&B10,CBIC_Late_Fee_Relief_Windows_3B!$E$10:$E$100,">="&B10,CBIC_Late_Fee_Relief_Windows_3B!$F$10:$F$100,"<="&C10,CBIC_Late_Fee_Relief_Windows_3B!$G$10:$G$100,">="&C10) | H10: =INDEX(CBIC_Late_Fee_Relief_Windows_3B!$I$10:$I$100,MATCH(G10,CBIC_Late_Fee_Relief_Windows_3B!$O$10:$O$100,0)) | I10: =MIN(F10,H10)
A11: =TEST_DATA!A11 | B11: =TEST_DATA!B11 | C11: =TEST_DATA!C11 | D11: =TEST_DATA!D11 | E11: =TEST_DATA!E11 | F11: =MIN(E11*1100,10000) | G11: =MINIFS(CBIC_Late_Fee_Relief_Windows_3B!$O$11:$O$100,CBIC_Late_Fee_Relief_Windows_3B!$D$11:$D$100,"<="&B11,CBIC_Late_Fee_Relief_Windows_3B!$E$11:$E$100,">="&B11,CBIC_Late_Fee_Relief_Windows_3B!$F$11:$F$100,"<="&C11,CBIC_Late_Fee_Relief_Windows_3B!$G$11:$G$100,">="&C11) | H11: =INDEX(CBIC_Late_Fee_Relief_Windows_3B!$I$11:$I$100,MATCH(G11,CBIC_Late_Fee_Relief_Windows_3B!$O$11:$O$100,0)) | I11: =MIN(F11,H11)
A12: =TEST_DATA!A12 | B12: =TEST_DATA!B12 | C12: =TEST_DATA!C12 | D12: =TEST_DATA!D12 | E12: =TEST_DATA!E12 | F12: =MIN(E12*1200,10000) | G12: =MINIFS(CBIC_Late_Fee_Relief_Windows_3B!$O$12:$O$100,CBIC_Late_Fee_Relief_Windows_3B!$D$12:$D$100,"<="&B12,CBIC_Late_Fee_Relief_Windows_3B!$E$12:$E$100,">="&B12,CBIC_Late_Fee_Relief_Windows_3B!$F$12:$F$100,"<="&C12,CBIC_Late_Fee_Relief_Windows_3B!$G$12:$G$100,">="&C12) | H12: =INDEX(CBIC_Late_Fee_Relief_Windows_3B!$I$12:$I$100,MATCH(G12,CBIC_Late_Fee_Relief_Windows_3B!$O$12:$O$100,0)) | I12: =MIN(F12,H12)
A13: =TEST_DATA!A13 | B13: =TEST_DATA!B13 | C13: =TEST_DATA!C13 | D13: =TEST_DATA!D13 | E13: =TEST_DATA!E13 | F13: =MIN(E13*1300,10000) | G13: =MINIFS(CBIC_Late_Fee_Relief_Windows_3B!$O$13:$O$100,CBIC_Late_Fee_Relief_Windows_3B!$D$13:$D$100,"<="&B13,CBIC_Late_Fee_Relief_Windows_3B!$E$13:$E$100,">="&B13,CBIC_Late_Fee_Relief_Windows_3B!$F$13:$F$100,"<="&C13,CBIC_Late_Fee_Relief_Windows_3B!$G$13:$G$100,">="&C13) | H13: =INDEX(CBIC_Late_Fee_Relief_Windows_3B!$I$13:$I$100,MATCH(G13,CBIC_Late_Fee_Relief_Windows_3B!$O$13:$O$100,0)) | I13: =MIN(F13,H13)
A14: =TEST_DATA!A14 | B14: =TEST_DATA!B14 | C14: =TEST_DATA!C14 | D14: =TEST_DATA!D14 | E14: =TEST_DATA!E14 | F14: =MIN(E14*1400,10000) | G14: =MINIFS(CBIC_Late_Fee_Relief_Windows_3B!$O$14:$O$100,CBIC_Late_Fee_Relief_Windows_3B!$D$14:$D$100,"<="&B14,CBIC_Late_Fee_Relief_Windows_3B!$E$14:$E$100,">="&B14,CBIC_Late_Fee_Relief_Windows_3B!$F$14:$F$100,"<="&C14,CBIC_Late_Fee_Relief_Windows_3B!$G$14:$G$100,">="&C14) | H14: =INDEX(CBIC_Late_Fee_Relief_Windows_3B!$I$14:$I$100,MATCH(G14,CBIC_Late_Fee_Relief_Windows_3B!$O$14:$O$100,0)) | I14: =MIN(F14,H14)
A15: =TEST_DATA!A15 | B15: =TEST_DATA!B15 | C15: =TEST_DATA!C15 | D15: =TEST_DATA!D15 | E15: =TEST_DATA!E15 | F15: =MIN(E15*1500,10000) | G15: =MINIFS(CBIC_Late_Fee_Relief_Windows_3B!$O$15:$O$100,CBIC_Late_Fee_Relief_Windows_3B!$D$15:$D$100,"<="&B15,CBIC_Late_Fee_Relief_Windows_3B!$E$15:$E$100,">="&B15,CBIC_Late_Fee_Relief_Windows_3B!$F$15:$F$100,"<="&C15,CBIC_Late_Fee_Relief_Windows_3B!$G$15:$G$100,">="&C15) | H15: =INDEX(CBIC_Late_Fee_Relief_Windows_3B!$I$15:$I$100,MATCH(G15,CBIC_Late_Fee_Relief_Windows_3B!$O$15:$O$100,0)) | I15: =MIN(F15,H15)
A16: =TEST_DATA!A16 | B16: =TEST_DATA!B16 | C16: =TEST_DATA!C16 | D16: =TEST_DATA!D16 | E16: =TEST_DATA!E16 | F16: =MIN(E16*1600,10000) | G16: =MINIFS(CBIC_Late_Fee_Relief_Windows_3B!$O$16:$O$100,CBIC_Late_Fee_Relief_Windows_3B!$D$16:$D$100,"<="&B16,CBIC_Late_Fee_Relief_Windows_3B!$E$16:$E$100,">="&B16,CBIC_Late_Fee_Relief_Windows_3B!$F$16:$F$100,"<="&C16,CBIC_Late_Fee_Relief_Windows_3B!$G$16:$G$100,">="&C16) | H16: =INDEX(CBIC_Late_Fee_Relief_Windows_3B!$I$16:$I$100,MATCH(G16,CBIC_Late_Fee_Relief_Windows_3B!$O$16:$O$100,0)) | I16: =MIN(F16,H16)
A17: =TEST_DATA!A17 | B17: =TEST_DATA!B17 | C17: =TEST_DATA!C17 | D17: =TEST_DATA!D17 | E17: =TEST_DATA!E17 | F17: =MIN(E17*1700,10000) | G17: =MINIFS(CBIC_Late_Fee_Relief_Windows_3B!$O$17:$O$100,CBIC_Late_Fee_Relief_Windows_3B!$D$17:$D$100,"<="&B17,CBIC_Late_Fee_Relief_Windows_3B!$E$17:$E$100,">="&B17,CBIC_Late_Fee_Relief_Windows_3B!$F$17:$F$100,"<="&C17,CBIC_Late_Fee_Relief_Windows_3B!$G$17:$G$100,">="&C17) | H17: =INDEX(CBIC_Late_Fee_Relief_Windows_3B!$I$17:$I$100,MATCH(G17,CBIC_Late_Fee_Relief_Windows_3B!$O$17:$O$100,0)) | I17: =MIN(F17,H17)
A18: =TEST_DATA!A18 | B18: =TEST_DATA!B18 | C18: =TEST_DATA!C18 | D18: =TEST_DATA!D18 | E18: =TEST_DATA!E18 | F18: =MIN(E18*1800,10000) | G18: =MINIFS(CBIC_Late_Fee_Relief_Windows_3B!$O$18:$O$100,CBIC_Late_Fee_Relief_Windows_3B!$D$18:$D$100,"<="&B18,CBIC_Late_Fee_Relief_Windows_3B!$E$18:$E$100,">="&B18,CBIC_Late_Fee_Relief_Windows_3B!$F$18:$F$100,"<="&C18,CBIC_Late_Fee_Relief_Windows_3B!$G$18:$G$100,">="&C18) | H18: =INDEX(CBIC_Late_Fee_Relief_Windows_3B!$I$18:$I$100,MATCH(G18,CBIC_Late_Fee_Relief_Windows_3B!$O$18:$O$100,0)) | I18: =MIN(F18,H18)
A19: =TEST_DATA!A19 | B19: =TEST_DATA!B19 | C19: =TEST_DATA!C19 | D19: =TEST_DATA!D19 | E19: =TEST_DATA!E19 | F19: =MIN(E19*1900,10000) | G19: =MINIFS(CBIC_Late_Fee_Relief_Windows_3B!$O$19:$O$100,CBIC_Late_Fee_Relief_Windows_3B!$D$19:$D$100,"<="&B19,CBIC_Late_Fee_Relief_Windows_3B!$E$19:$E$100,">="&B19,CBIC_Late_Fee_Relief_Windows_3B!$F$19:$F$100,"<="&C19,CBIC_Late_Fee_Relief_Windows_3B!$G$19:$G$100,">="&C19) | H19: =INDEX(CBIC_Late_Fee_Relief_Windows_3B!$I$19:$I$100,MATCH(G19,CBIC_Late_Fee_Relief_Windows_3B!$O$19:$O$100,0)) | I19: =MIN(F19,H19)
A20: =TEST_DATA!A20 | B20: =TEST_DATA!B20 | C20: =TEST_DATA!C20 | D20: =TEST_DATA!D20 | E20: =TEST_DATA!E20 | F20: =MIN(E20*2000,10000) | G20: =MINIFS(CBIC_Late_Fee_Relief_Windows_3B!$O$20:$O$100,CBIC_Late_Fee_Relief_Windows_3B!$D$20:$D$100,"<="&B20,CBIC_Late_Fee_Relief_Windows_3B!$E$20:$E$100,">="&B20,CBIC_Late_Fee_Relief_Windows_3B!$F$20:$F$100,"<="&C20,CBIC_Late_Fee_Relief_Windows_3B!$G$20:$G$100,">="&C20) | H20: =INDEX(CBIC_Late_Fee_Relief_Windows_3B!$I$20:$I$100,MATCH(G20,CBIC_Late_Fee_Relief_Windows_3B!$O$20:$O$100,0)) | I20: =MIN(F20,H20)
A21: =TEST_DATA!A21 | B21: =TEST_DATA!B21 | C21: =TEST_DATA!C21 | D21: =TEST_DATA!D21 | E21: =TEST_DATA!E21 | F21: =MIN(E21*2100,10000) | G21: =MINIFS(CBIC_Late_Fee_Relief_Windows_3B!$O$21:$O$100,CBIC_Late_Fee_Relief_Windows_3B!$D$21:$D$100,"<="&B21,CBIC_Late_Fee_Relief_Windows_3B!$E$21:$E$100,">="&B21,CBIC_Late_Fee_Relief_Windows_3B!$F$21:$F$100,"<="&C21,CBIC_Late_Fee_Relief_Windows_3B!$G$21:$G$100,">="&C21) | H21: =INDEX(CBIC_Late_Fee_Relief_Windows_3B!$I$21:$I$100,MATCH(G21,CBIC_Late_Fee_Relief_Windows_3B!$O$21:$O$100,0)) | I21: =MIN(F21,H21)
A22: =TEST_DATA!A22 | B22: =TEST_DATA!B22 | C22: =TEST_DATA!C22 | D22: =TEST_DATA!D22 | E22: =TEST_DATA!E22 | F22: =MIN(E22*2200,10000) | G22: =MINIFS(CBIC_Late_Fee_Relief_Windows_3B!$O$22:$O$100,CBIC_Late_Fee_Relief_Windows_3B!$D$22:$D$100,"<="&B22,CBIC_Late_Fee_Relief_Windows_3B!$E$22:$E$100,">="&B22,CBIC_Late_Fee_Relief_Windows_3B!$F$22:$F$100,"<="&C22,CBIC_Late_Fee_Relief_Windows_3B!$G$22:$G$100,">="&C22) | H22: =INDEX(CBIC_Late_Fee_Relief_Windows_3B!$I$22:$I$100,MATCH(G22,CBIC_Late_Fee_Relief_Windows_3B!$O$22:$O$100,0)) | I22: =MIN(F22,H22)
A23: =TEST_DATA!A23 | B23: =TEST_DATA!B23 | C23: =TEST_DATA!C23 | D23: =TEST_DATA!D23 | E23: =TEST_DATA!E23 | F23: =MIN(E23*2300,10000) | G23: =MINIFS(CBIC_Late_Fee_Relief_Windows_3B!$O$23:$O$100,CBIC_Late_Fee_Relief_Windows_3B!$D$23:$D$100,"<="&B23,CBIC_Late_Fee_Relief_Windows_3B!$E$23:$E$100,">="&B23,CBIC_Late_Fee_Relief_Windows_3B!$F$23:$F$100,"<="&C23,CBIC_Late_Fee_Relief_Windows_3B!$G$23:$G$100,">="&C23) | H23: =INDEX(CBIC_Late_Fee_Relief_Windows_3B!$I$23:$I$100,MATCH(G23,CBIC_Late_Fee_Relief_Windows_3B!$O$23:$O$100,0)) | I23: =MIN(F23,H23)
A24: =TEST_DATA!A24 | B24: =TEST_DATA!B24 | C24: =TEST_DATA!C24 | D24: =TEST_DATA!D24 | E24: =TEST_DATA!E24 | F24: =MIN(E24*2400,10000) | G24: =MINIFS(CBIC_Late_Fee_Relief_Windows_3B!$O$24:$O$100,CBIC_Late_Fee_Relief_Windows_3B!$D$24:$D$100,"<="&B24,CBIC_Late_Fee_Relief_Windows_3B!$E$24:$E$100,">="&B24,CBIC_Late_Fee_Relief_Windows_3B!$F$24:$F$100,"<="&C24,CBIC_Late_Fee_Relief_Windows_3B!$G$24:$G$100,">="&C24) | H24: =INDEX(CBIC_Late_Fee_Relief_Windows_3B!$I$24:$I$100,MATCH(G24,CBIC_Late_Fee_Relief_Windows_3B!$O$24:$O$100,0)) | I24: =MIN(F24,H24)
A25: =TEST_DATA!A25 | B25: =TEST_DATA!B25 | C25: =TEST_DATA!C25 | D25: =TEST_DATA!D25 | E25: =TEST_DATA!E25 | F25: =MIN(E25*2500,10000) | G25: =MINIFS(CBIC_Late_Fee_Relief_Windows_3B!$O$25:$O$100,CBIC_Late_Fee_Relief_Windows_3B!$D$25:$D$100,"<="&B25,CBIC_Late_Fee_Relief_Windows_3B!$E$25:$E$100,">="&B25,CBIC_Late_Fee_Relief_Windows_3B!$F$25:$F$100,"<="&C25,CBIC_Late_Fee_Relief_Windows_3B!$G$25:$G$100,">="&C25) | H25: =INDEX(CBIC_Late_Fee_Relief_Windows_3B!$I$25:$I$100,MATCH(G25,CBIC_Late_Fee_Relief_Windows_3B!$O$25:$O$100,0)) | I25: =MIN(F25,H25)
A26: =TEST_DATA!A26 | B26: =TEST_DATA!B26 | C26: =TEST_DATA!C26 | D26: =TEST_DATA!D26 | E26: =TEST_DATA!E26 | F26: =MIN(E26*2600,10000) | G26: =MINIFS(CBIC_Late_Fee_Relief_Windows_3B!$O$26:$O$100,CBIC_Late_Fee_Relief_Windows_3B!$D$26:$D$100,"<="&B26,CBIC_Late_Fee_Relief_Windows_3B!$E$26:$E$100,">="&B26,CBIC_Late_Fee_Relief_Windows_3B!$F$26:$F$100,"<="&C26,CBIC_Late_Fee_Relief_Windows_3B!$G$26:$G$100,">="&C26) | H26: =INDEX(CBIC_Late_Fee_Relief_Windows_3B!$I$26:$I$100,MATCH(G26,CBIC_Late_Fee_Relief_Windows_3B!$O$26:$O$100,0)) | I26: =MIN(F26,H26)
A27: =TEST_DATA!A27 | B27: =TEST_DATA!B27 | C27: =TEST_DATA!C27 | D27: =TEST_DATA!D27 | E27: =TEST_DATA!E27 | F27: =MIN(E27*2700,10000) | G27: =MINIFS(CBIC_Late_Fee_Relief_Windows_3B!$O$27:$O$100,CBIC_Late_Fee_Relief_Windows_3B!$D$27:$D$100,"<="&B27,CBIC_Late_Fee_Relief_Windows_3B!$E$27:$E$100,">="&B27,CBIC_Late_Fee_Relief_Windows_3B!$F$27:$F$100,"<="&C27,CBIC_Late_Fee_Relief_Windows_3B!$G$27:$G$100,">="&C27) | H27: =INDEX(CBIC_Late_Fee_Relief_Windows_3B!$I$27:$I$100,MATCH(G27,CBIC_Late_Fee_Relief_Windows_3B!$O$27:$O$100,0)) | I27: =MIN(F27,H27)
A28: =TEST_DATA!A28 | B28: =TEST_DATA!B28 | C28: =TEST_DATA!C28 | D28: =TEST_DATA!D28 | E28: =TEST_DATA!E28 | F28: =MIN(E28*2800,10000) | G28: =MINIFS(CBIC_Late_Fee_Relief_Windows_3B!$O$28:$O$100,CBIC_Late_Fee_Relief_Windows_3B!$D$28:$D$100,"<="&B28,CBIC_Late_Fee_Relief_Windows_3B!$E$28:$E$100,">="&B28,CBIC_Late_Fee_Relief_Windows_3B!$F$28:$F$100,"<="&C28,CBIC_Late_Fee_Relief_Windows_3B!$G$28:$G$100,">="&C28) | H28: =INDEX(CBIC_Late_Fee_Relief_Windows_3B!$I$28:$I$100,MATCH(G28,CBIC_Late_Fee_Relief_Windows_3B!$O$28:$O$100,0)) | I28: =MIN(F28,H28)
A29: =TEST_DATA!A29 | B29: =TEST_DATA!B29 | C29: =TEST_DATA!C29 | D29: =TEST_DATA!D29 | E29: =TEST_DATA!E29 | F29: =MIN(E29*2900,10000) | G29: =MINIFS(CBIC_Late_Fee_Relief_Windows_3B!$O$29:$O$100,CBIC_Late_Fee_Relief_Windows_3B!$D$29:$D$100,"<="&B29,CBIC_Late_Fee_Relief_Windows_3B!$E$29:$E$100,">="&B29,CBIC_Late_Fee_Relief_Windows_3B!$F$29:$F$100,"<="&C29,CBIC_Late_Fee_Relief_Windows_3B!$G$29:$G$100,">="&C29) | H29: =INDEX(CBIC_Late_Fee_Relief_Windows_3B!$I$29:$I$100,MATCH(G29,CBIC_Late_Fee_Relief_Windows_3B!$O$29:$O$100,0)) | I29: =MIN(F29,H29)
A30: =TEST_DATA!A30 | B30: =TEST_DATA!B30 | C30: =TEST_DATA!C30 | D30: =TEST_DATA!D30 | E30: =TEST_DATA!E30 | F30: =MIN(E30*3000,10000) | G30: =MINIFS(CBIC_Late_Fee_Relief_Windows_3B!$O$30:$O$100,CBIC_Late_Fee_Relief_Windows_3B!$D$30:$D$100,"<="&B30,CBIC_Late_Fee_Relief_Windows_3B!$E$30:$E$100,">="&B30,CBIC_Late_Fee_Relief_Windows_3B!$F$30:$F$100,"<="&C30,CBIC_Late_Fee_Relief_Windows_3B!$G$30:$G$100,">="&C30) | H30: =INDEX(CBIC_Late_Fee_Relief_Windows_3B!$I$30:$I$100,MATCH(G30,CBIC_Late_Fee_Relief_Windows_3B!$O$30:$O$100,0)) | I30: =MIN(F30,H30)
A31: =TEST_DATA!A31 | B31: =TEST_DATA!B31 | C31: =TEST_DATA!C31 | D31: =TEST_DATA!D31 | E31: =TEST_DATA!E31 | F31: =MIN(E31*3100,10000) | G31: =MINIFS(CBIC_Late_Fee_Relief_Windows_3B!$O$31:$O$100,CBIC_Late_Fee_Relief_Windows_3B!$D$31:$D$100,"<="&B31,CBIC_Late_Fee_Relief_Windows_3B!$E$31:$E$100,">="&B31,CBIC_Late_Fee_Relief_Windows_3B!$F$31:$F$100,"<="&C31,CBIC_Late_Fee_Relief_Windows_3B!$G$31:$G$100,">="&C31) | H31: =INDEX(CBIC_Late_Fee_Relief_Windows_3B!$I$31:$I$100,MATCH(G31,CBIC_Late_Fee_Relief_Windows_3B!$O$31:$O$100,0)) | I31: =MIN(F31,H31)
A32: =TEST_DATA!A32 | B32: =TEST_DATA!B32 | C32: =TEST_DATA!C32 | D32: =TEST_DATA!D32 | E32: =TEST_DATA!E32 | F32: =MIN(E32*3200,10000) | G32: =MINIFS(CBIC_Late_Fee_Relief_Windows_3B!$O$32:$O$100,CBIC_Late_Fee_Relief_Windows_3B!$D$32:$D$100,"<="&B32,CBIC_Late_Fee_Relief_Windows_3B!$E$32:$E$100,">="&B32,CBIC_Late_Fee_Relief_Windows_3B!$F$32:$F$100,"<="&C32,CBIC_Late_Fee_Relief_Windows_3B!$G$32:$G$100,">="&C32) | H32: =INDEX(CBIC_Late_Fee_Relief_Windows_3B!$I$32:$I$100,MATCH(G32,CBIC_Late_Fee_Relief_Windows_3B!$O$32:$O$100,0)) | I32: =MIN(F32,H32)
A33: =TEST_DATA!A33 | B33: =TEST_DATA!B33 | C33: =TEST_DATA!C33 | D33: =TEST_DATA!D33 | E33: =TEST_DATA!E33 | F33: =MIN(E33*3300,10000) | G33: =MINIFS(CBIC_Late_Fee_Relief_Windows_3B!$O$33:$O$100,CBIC_Late_Fee_Relief_Windows_3B!$D$33:$D$100,"<="&B33,CBIC_Late_Fee_Relief_Windows_3B!$E$33:$E$100,">="&B33,CBIC_Late_Fee_Relief_Windows_3B!$F$33:$F$100,"<="&C33,CBIC_Late_Fee_Relief_Windows_3B!$G$33:$G$100,">="&C33) | H33: =INDEX(CBIC_Late_Fee_Relief_Windows_3B!$I$33:$I$100,MATCH(G33,CBIC_Late_Fee_Relief_Windows_3B!$O$33:$O$100,0)) | I33: =MIN(F33,H33)
A34: =TEST_DATA!A34 | B34: =TEST_DATA!B34 | C34: =TEST_DATA!C34 | D34: =TEST_DATA!D34 | E34: =TEST_DATA!E34 | F34: =MIN(E34*3400,10000) | G34: =MINIFS(CBIC_Late_Fee_Relief_Windows_3B!$O$34:$O$100,CBIC_Late_Fee_Relief_Windows_3B!$D$34:$D$100,"<="&B34,CBIC_Late_Fee_Relief_Windows_3B!$E$34:$E$100,">="&B34,CBIC_Late_Fee_Relief_Windows_3B!$F$34:$F$100,"<="&C34,CBIC_Late_Fee_Relief_Windows_3B!$G$34:$G$100,">="&C34) | H34: =INDEX(CBIC_Late_Fee_Relief_Windows_3B!$I$34:$I$100,MATCH(G34,CBIC_Late_Fee_Relief_Windows_3B!$O$34:$O$100,0)) | I34: =MIN(F34,H34)
A35: =TEST_DATA!A35 | B35: =TEST_DATA!B35 | C35: =TEST_DATA!C35 | D35: =TEST_DATA!D35 | E35: =TEST_DATA!E35 | F35: =MIN(E35*3500,10000) | G35: =MINIFS(CBIC_Late_Fee_Relief_Windows_3B!$O$35:$O$100,CBIC_Late_Fee_Relief_Windows_3B!$D$35:$D$100,"<="&B35,CBIC_Late_Fee_Relief_Windows_3B!$E$35:$E$100,">="&B35,CBIC_Late_Fee_Relief_Windows_3B!$F$35:$F$100,"<="&C35,CBIC_Late_Fee_Relief_Windows_3B!$G$35:$G$100,">="&C35) | H35: =INDEX(CBIC_Late_Fee_Relief_Windows_3B!$I$35:$I$100,MATCH(G35,CBIC_Late_Fee_Relief_Windows_3B!$O$35:$O$100,0)) | I35: =MIN(F35,H35)
A36: =TEST_DATA!A36 | B36: =TEST_DATA!B36 | C36: =TEST_DATA!C36 | D36: =TEST_DATA!D36 | E36: =TEST_DATA!E36 | F36: =MIN(E36*3600,10000) | G36: =MINIFS(CBIC_Late_Fee_Relief_Windows_3B!$O$36:$O$100,CBIC_Late_Fee_Relief_Windows_3B!$D$36:$D$100,"<="&B36,CBIC_Late_Fee_Relief_Windows_3B!$E$36:$E$100,">="&B36,CBIC_Late_Fee_Relief_Windows_3B!$F$36:$F$100,"<="&C36,CBIC_Late_Fee_Relief_Windows_3B!$G$36:$G$100,">="&C36) | H36: =INDEX(CBIC_Late_Fee_Relief_Windows_3B!$I$36:$I$100,MATCH(G36,CBIC_Late_Fee_Relief_Windows_3B!$O$36:$O$100,0)) | I36: =MIN(F36,H36)
A37: =TEST_DATA!A37 | B37: =TEST_DATA!B37 | C37: =TEST_DATA!C37 | D37: =TEST_DATA!D37 | E37: =TEST_DATA!E37 | F37: =MIN(E37*3700,10000) | G37: =MINIFS(CBIC_Late_Fee_Relief_Windows_3B!$O$37:$O$100,CBIC_Late_Fee_Relief_Windows_3B!$D$37:$D$100,"<="&B37,CBIC_Late_Fee_Relief_Windows_3B!$E$37:$E$100,">="&B37,CBIC_Late_Fee_Relief_Windows_3B!$F$37:$F$100,"<="&C37,CBIC_Late_Fee_Relief_Windows_3B!$G$37:$G$100,">="&C37) | H37: =INDEX(CBIC_Late_Fee_Relief_Windows_3B!$I$37:$I$100,MATCH(G37,CBIC_Late_Fee_Relief_Windows_3B!$O$37:$O$100,0)) | I37: =MIN(F37,H37)
A38: =TEST_DATA!A38 | B38: =TEST_DATA!B38 | C38: =TEST_DATA!C38 | D38: =TEST_DATA!D38 | E38: =TEST_DATA!E38 | F38: =MIN(E38*3800,10000) | G38: =MINIFS(CBIC_Late_Fee_Relief_Windows_3B!$O$38:$O$100,CBIC_Late_Fee_Relief_Windows_3B!$D$38:$D$100,"<="&B38,CBIC_Late_Fee_Relief_Windows_3B!$E$38:$E$100,">="&B38,CBIC_Late_Fee_Relief_Windows_3B!$F$38:$F$100,"<="&C38,CBIC_Late_Fee_Relief_Windows_3B!$G$38:$G$100,">="&C38) | H38: =INDEX(CBIC_Late_Fee_Relief_Windows_3B!$I$38:$I$100,MATCH(G38,CBIC_Late_Fee_Relief_Windows_3B!$O$38:$O$100,0)) | I38: =MIN(F38,H38)
A39: =TEST_DATA!A39 | B39: =TEST_DATA!B39 | C39: =TEST_DATA!C39 | D39: =TEST_DATA!D39 | E39: =TEST_DATA!E39 | F39: =MIN(E39*3900,10000) | G39: =MINIFS(CBIC_Late_Fee_Relief_Windows_3B!$O$39:$O$100,CBIC_Late_Fee_Relief_Windows_3B!$D$39:$D$100,"<="&B39,CBIC_Late_Fee_Relief_Windows_3B!$E$39:$E$100,">="&B39,CBIC_Late_Fee_Relief_Windows_3B!$F$39:$F$100,"<="&C39,CBIC_Late_Fee_Relief_Windows_3B!$G$39:$G$100,">="&C39) | H39: =INDEX(CBIC_Late_Fee_Relief_Windows_3B!$I$39:$I$100,MATCH(G39,CBIC_Late_Fee_Relief_Windows_3B!$O$39:$O$100,0)) | I39: =MIN(F39,H39)
A40: =TEST_DATA!A40 | B40: =TEST_DATA!B40 | C40: =TEST_DATA!C40 | D40: =TEST_DATA!D40 | E40: =TEST_DATA!E40 | F40: =MIN(E40*4000,10000) | G40: =MINIFS(CBIC_Late_Fee_Relief_Windows_3B!$O$40:$O$100,CBIC_Late_Fee_Relief_Windows_3B!$D$40:$D$100,"<="&B40,CBIC_Late_Fee_Relief_Windows_3B!$E$40:$E$100,">="&B40,CBIC_Late_Fee_Relief_Windows_3B!$F$40:$F$100,"<="&C40,CBIC_Late_Fee_Relief_Windows_3B!$G$40:$G$100,">="&C40) | H40: =INDEX(CBIC_Late_Fee_Relief_Windows_3B!$I$40:$I$100,MATCH(G40,CBIC_Late_Fee_Relief_Windows_3B!$O$40:$O$100,0)) | I40: =MIN(F40,H40)
...

Sheet TEST_DATA
A1: GSTIN | B1: Tax Period | C1: Filing Date | D1: Return Type | E1: Delay Days
A2: 27BBBBB00002Z5 | B2: Dec-2018 | C2: 43934 | D2: NON-NIL | E2: 105
A3: 27BBBBB00003Z5 | B3: Nov-2018 | C3: 44289 | D3: NIL | E3: 1462
A4: 27BBBBB00004Z5 | B4: May-2020 | C4: 44772 | D4: NIL | E4: 276
A5: 27BBBBB00005Z5 | B5: Mar-2023 | C5: 45504 | D5: NON-NIL | E5: 2589
A6: 27BBBBB00006Z5 | B6: Apr-2018 | C6: 43488 | D6: NIL | E6: 247
A7: 27BBBBB00007Z5 | B7: Nov-2017 | C7: 44418 | D7: NON-NIL | E7: 1066
A8: 27BBBBB00008Z5 | B8: Mar-2021 | C8: 45550 | D8: NON-NIL | E8: 696
A9: 27BBBBB00009Z5 | B9: Mar-2018 | C9: 43545 | D9: NIL | E9: 1808
A10: 27BBBBB00010Z5 | B10: Apr-2020 | C10: 44250 | D10: NON-NIL | E10: 1596
A11: 27BBBBB00011Z5 | B11: Aug-2018 | C11: 43023 | D11: NON-NIL | E11: 1267
A12: 27BBBBB00012Z5 | B12: Dec-2018 | C12: 44464 | D12: NON-NIL | E12: 1878
A13: 27BBBBB00013Z5 | B13: Oct-2017 | C13: 43161 | D13: NIL | E13: 1667
... A20001: 27BBBBB20001Z5 | B20001: Mar-2021 | C20001: 44478 | D20001: NIL | E20001: 2218

Sheet ASSERTIONS
A1: Assertion | B1: Formula | C1: Result
A2: Final LF <= 10000 | B2: =COUNTIF(Late_Fee_Calculator_3B!I2:I20001,">10000") | C2: =IF(B2=0,"PASS","FAIL")
A3: No blank Final LF | B3: =COUNTBLANK(Late_Fee_Calculator_3B!I2:I20001) | C3: =IF(B3=0,"PASS","FAIL")
A4: Final LF <= Normal LF | B4: =COUNTIF(Late_Fee_Calculator_3B!I2:I20001,">"&Late_Fee_Calculator_3B!F2:F20001) | C4: =IF(B4=0,"PASS","FAIL")
